Workbook

Sheet Total Summary
B1: Strategic Sourcing - Provisional Sum Department
B2: ARR Summary
A4: A | B4: Total ARR Awarded Based on Location
E5: PS Budget incl OH&P | F5: PS Awarded | G5: Saving | H5: % of Awarded
B6: Total For | C6: Abu Dhabi | E6: =SUMIFS('ARR '!$G$4:$G$176,'ARR '!$M$4:$M$176,$C6,'ARR '!$N$4:$N$176,$C$13) -> 1.6049213e+08 | F6: =SUMIFS('ARR '!$H$4:$H$176,'ARR '!$M$4:$M$176,$C6,'ARR '!$N$4:$N$176,$C$13) -> 1.4981273e+08 | G6: =SUMIFS('ARR '!$I$4:$I$176,'ARR '!$M$4:$M$176,'Total Summary'!$C6,'ARR '!$N$4:$N$176,'Total Summary'!$C$13) -> 10679399 | H6: =F6/'ARR '!H177 -> 0.41331059
B7: Total For | C7: Dubai | E7: =SUMIFS('ARR '!$G$4:$G$176,'ARR '!$M$4:$M$176,$C7,'ARR '!$N$4:$N$176,$C$13) -> 39004168 | F7: =SUMIFS('ARR '!$H$4:$H$176,'ARR '!$M$4:$M$176,$C7,'ARR '!$N$4:$N$176,$C$13) -> 21936231 | G7: =SUMIFS('ARR '!$I$4:$I$176,'ARR '!$M$4:$M$176,'Total Summary'!$C7,'ARR '!$N$4:$N$176,'Total Summary'!$C$13) -> 17067937 | H7: =F7/'ARR '!H177 -> 0.060518734
B8: Total For | C8: RAK | E8: =SUMIFS('ARR '!$G$4:$G$176,'ARR '!$M$4:$M$176,$C8,'ARR '!$N$4:$N$176,$C$13) -> 242800000 | F8: =SUMIFS('ARR '!$H$4:$H$176,'ARR '!$M$4:$M$176,$C8,'ARR '!$N$4:$N$176,$C$13) -> 1.7358384e+08 | G8: =SUMIFS('ARR '!$I$4:$I$176,'ARR '!$M$4:$M$176,'Total Summary'!$C8,'ARR '!$N$4:$N$176,'Total Summary'!$C$13) -> 69216158 | H8: =F8/'ARR '!H177 -> 0.47889149
C9: Overall total | E9: =SUM(E6:E8) -> 4.422963e+08 | F9: =SUM(F6:F8) -> 3.453328e+08 | G9: =SUM(G6:G8) -> 96963494 | H9: =SUM(H6:H8) -> 0.95272082
A11: B | B11: Awarded / Ongoing
B13: Total for | C13: Awarded | E13: =SUMIF('ARR '!$N$4:$N$176,C13,'ARR '!$G$4:$G$176) -> 4.422963e+08 | F13: =SUMIF('ARR '!$N$4:$N$176,C13,'ARR '!$H$4:$H$176) -> 3.453328e+08 | G13: =SUMIF('ARR '!$N$4:$N$176,C13,'ARR '!$I$4:$I$176) -> 96963494
B14: Total for | C14: Ongoing | E14: =SUMIF('ARR '!$N$4:$N$176,C14,'ARR '!$G$4:$G$176) -> 5.4675655e+08 | F14: =SUMIF('ARR '!$N$4:$N$176,C14,'ARR '!$H$4:$H$176) -> 17137290 | G14: =SUMIF('ARR '!$N$4:$N$176,C14,'ARR '!$I$4:$I$176) -> -2692194
C15: Overall total | E15: =SUM(E13:E14) -> 9.8905285e+08 | F15: =SUM(F13:F14) -> 3.6247009e+08 | G15: =SUM(G13:G14) -> 94271300
A18: C | B18: Total Awarded based on Staff
E19: No of Packages | F19: Total Awarded | G19: Total Saving | H19: %
C20: Anil | E20: =COUNTIFS('ARR '!$L$4:$L$176,'Total Summary'!$C20,'ARR '!$N$4:$N$176,'Total Summary'!$C$13) -> 0 | F20: =SUMIFS('ARR '!$H$4:$H$176,'ARR '!$L$4:$L$176,'Total Summary'!$C20,'ARR '!$N$4:$N$176,'Total Summary'!$C$13) -> 0 | G20: =SUMIFS('ARR '!$I$4:$I$176,'ARR '!$L$4:$L$176,'Total Summary'!$C20,'ARR '!$N$4:$N$176,'Total Summary'!$C$13) -> 0 | H20: =E20/$E$30 -> 0
C21: Prabhu | E21: =COUNTIFS('ARR '!$L$4:$L$176,'Total Summary'!$C21,'ARR '!$N$4:$N$176,'Total Summary'!$C$13) -> 3 | F21: =SUMIFS('ARR '!$H$4:$H$176,'ARR '!$L$4:$L$176,'Total Summary'!$C21,'ARR '!$N$4:$N$176,'Total Summary'!$C$13) -> 28533905 | G21: =SUMIFS('ARR '!$I$4:$I$176,'ARR '!$L$4:$L$176,'Total Summary'!$C21,'ARR '!$N$4:$N$176,'Total Summary'!$C$13) -> -2173246 | H21: =E21/$E$30 -> 0.125
C22: Manoj | E22: =COUNTIFS('ARR '!$L$4:$L$176,'Total Summary'!$C22,'ARR '!$N$4:$N$176,'Total Summary'!$C$13) -> 3 | F22: =SUMIFS('ARR '!$H$4:$H$176,'ARR '!$L$4:$L$176,'Total Summary'!$C22,'ARR '!$N$4:$N$176,'Total Summary'!$C$13) -> 50841356 | G22: =SUMIFS('ARR '!$I$4:$I$176,'ARR '!$L$4:$L$176,'Total Summary'!$C22,'ARR '!$N$4:$N$176,'Total Summary'!$C$13) -> 3656010.2 | H22: =E22/$E$30 -> 0.125
C23: Iftikhar | E23: =COUNTIFS('ARR '!$L$4:$L$176,'Total Summary'!$C23,'ARR '!$N$4:$N$176,'Total Summary'!$C$13) -> 4 | F23: =SUMIFS('ARR '!$H$4:$H$176,'ARR '!$L$4:$L$176,'Total Summary'!$C23,'ARR '!$N$4:$N$176,'Total Summary'!$C$13) -> 47288743 | G23: =SUMIFS('ARR '!$I$4:$I$176,'ARR '!$L$4:$L$176,'Total Summary'!$C23,'ARR '!$N$4:$N$176,'Total Summary'!$C$13) -> 29224257 | H23: =E23/$E$30 -> 0.16666667
C24: Alber | E24: =COUNTIFS('ARR '!$L$4:$L$176,'Total Summary'!$C24,'ARR '!$N$4:$N$176,'Total Summary'!$C$13) -> 3 | F24: =SUMIFS('ARR '!$H$4:$H$176,'ARR '!$L$4:$L$176,'Total Summary'!$C24,'ARR '!$N$4:$N$176,'Total Summary'!$C$13) -> 6670883 | G24: =SUMIFS('ARR '!$I$4:$I$176,'ARR '!$L$4:$L$176,'Total Summary'!$C24,'ARR '!$N$4:$N$176,'Total Summary'!$C$13) -> 2132940 | H24: =E24/$E$30 -> 0.125
C25: Abeer | E25: =COUNTIFS('ARR '!$L$4:$L$176,'Total Summary'!$C25,'ARR '!$N$4:$N$176,'Total Summary'!$C$13) -> 0 | F25: =SUMIFS('ARR '!$H$4:$H$176,'ARR '!$L$4:$L$176,'Total Summary'!$C25,'ARR '!$N$4:$N$176,'Total Summary'!$C$13) -> 0 | G25: =SUMIFS('ARR '!$I$4:$I$176,'ARR '!$L$4:$L$176,'Total Summary'!$C25,'ARR '!$N$4:$N$176,'Total Summary'!$C$13) -> 0 | H25: =E25/$E$30 -> 0
C26: Suhail | E26: =COUNTIFS('ARR '!$L$4:$L$176,'Total Summary'!$C26,'ARR '!$N$4:$N$176,'Total Summary'!$C$13) -> 3 | F26: =SUMIFS('ARR '!$H$4:$H$176,'ARR '!$L$4:$L$176,'Total Summary'!$C26,'ARR '!$N$4:$N$176,'Total Summary'!$C$13) -> 1.7862546e+08 | G26: =SUMIFS('ARR '!$I$4:$I$176,'ARR '!$L$4:$L$176,'Total Summary'!$C26,'ARR '!$N$4:$N$176,'Total Summary'!$C$13) -> 62326070 | H26: =E26/$E$30 -> 0.125
C27: Reyoon | E27: =COUNTIFS('ARR '!$L$4:$L$176,'Total Summary'!$C27,'ARR '!$N$4:$N$176,'Total Summary'!$C$13) -> 6 | F27: =SUMIFS('ARR '!$H$4:$H$176,'ARR '!$L$4:$L$176,'Total Summary'!$C27,'ARR '!$N$4:$N$176,'Total Summary'!$C$13) -> 28112522 | G27: =SUMIFS('ARR '!$I$4:$I$176,'ARR '!$L$4:$L$176,'Total Summary'!$C27,'ARR '!$N$4:$N$176,'Total Summary'!$C$13) -> 2448906.2 | H27: =E27/$E$30 -> 0.25
C28: Frameworks Agreement | E28: =COUNTIFS('ARR '!$L$4:$L$176,'Total Summary'!$C28,'ARR '!$N$4:$N$176,'Total Summary'!$C$13) -> 2 | F28: =SUMIFS('ARR '!$H$4:$H$176,'ARR '!$L$4:$L$176,'Total Summary'!$C28,'ARR '!$N$4:$N$176,'Total Summary'!$C$13) -> 5259932.6 | G28: =SUMIFS('ARR '!$I$4:$I$176,'ARR '!$L$4:$L$176,'Total Summary'!$C28,'ARR '!$N$4:$N$176,'Total Summary'!$C$13) -> -651443.02 | H28: =E28/$E$30 -> 0.083333333
C30: Overall total | E30: =SUM(E20:E29) -> 24 | F30: =SUM(F20:F29) -> 3.453328e+08 | G30: =SUM(G20:G29) -> 96963494
A32: D | B32: Total Awarded base on Months
B33: Description | C33: Month | F33: Toral Awarded | H33: %
B34: Total Awarded on | C34: 45992 | F34: =SUMIF('ARR '!$K$4:$K$176,C34,'ARR '!$H$4:$H$176) -> 4355584 | H34: =F34/$F$49 -> 0.012016396
B35: Total Awarded on | C35: 46023 | F35: =SUMIF('ARR '!$K$4:$K$176,C35,'ARR '!$H$4:$H$176) -> 26978980 | H35: =F35/$F$49 -> 0.074430913
B36: Total Awarded on | C36: 46054 | F36: =SUMIF('ARR '!$K$4:$K$176,C36,'ARR '!$H$4:$H$176) -> 1969878.2 | H36: =F36/$F$49 -> 0.005434595
B37: Total Awarded on | C37: 46082 | F37: =SUMIF('ARR '!$K$4:$K$176,C37,'ARR '!$H$4:$H$176) -> 10704455 | H37: =F37/$F$49 -> 0.029531969
B38: Total Awarded on | C38: Apr 2026 | F38: =SUMIF('ARR '!$K$4:$K$176,C38,'ARR '!$H$4:$H$176) -> 1.6077931e+08 | H38: =F38/$F$49 -> 0.44356572
B39: Total Awarded on | C39: May 2026 | F39: =SUMIF('ARR '!$K$4:$K$176,C39,'ARR '!$H$4:$H$176) -> 1.1575009e+08 | H39: =F39/$F$49 -> 0.31933694
B40: Total Awarded on | C40: 46174 | F40: =SUMIF('ARR '!$K$4:$K$176,C40,'ARR '!$H$4:$H$176) -> 41931797 | H40: =F40/$F$49 -> 0.11568347
B41: Total Awarded on | C41: 46204
B42: Total Awarded on | C42: 46235
B43: Total Awarded on | C43: 46266
B44: Total Awarded on | C44: 46296
B45: Total Awarded on | C45: 46327
B46: Total Awarded on | C46: 46357
B47: Total Awarded on
...

Sheet High Levela Summary
A4: Strategic Sourcing - Provisional Sum Department
A6: ARR Summary
A8: Overall Status | Q8: Location-wise split
D10: PS Budget incl OH&P | G10: Awarded PS | J10: Savings | T10: PS Budget incl OH&P | W10: Awarded PS | Z10: Savings | AC10: % Awarded
B12: Awarded | D12: ='Total Summary'!E13 -> 4.422963e+08 | G12: ='Total Summary'!F13 -> 3.453328e+08 | J12: ='Total Summary'!G13 -> 96963494 | R12: Abu Dhabi | T12: ='Total Summary'!E6 -> 1.6049213e+08 | W12: ='Total Summary'!F6 -> 1.4981273e+08 | Z12: ='Total Summary'!G6 -> 10679399 | AC12: ='Total Summary'!H6 -> 0.41331059
B13: Ongoing | D13: ='Total Summary'!E14 -> 5.4675655e+08 | G13: ='Total Summary'!F14 -> 17137290 | J13: ='Total Summary'!G14 -> -2692194 | R13: RAK | T13: ='Total Summary'!E8 -> 242800000 | W13: ='Total Summary'!F8 -> 1.7358384e+08 | Z13: ='Total Summary'!G8 -> 69216158 | AC13: ='Total Summary'!H8 -> 0.47889149
R14: Dubai | T14: ='Total Summary'!E7 -> 39004168 | W14: ='Total Summary'!F7 -> 21936231 | Z14: ='Total Summary'!G7 -> 17067937 | AC14: ='Total Summary'!H7 -> 0.060518734
B16: Total | D16: =D13+D12 -> 9.8905285e+08 | G16: =G13+G12 -> 3.6247009e+08 | J16: =J13+J12 -> 94271300 | R16: Total | T16: =SUM(T12:U15) -> 4.422963e+08 | W16: =SUM(W12:X15) -> 3.453328e+08 | Z16: =SUM(Z12:AA15) -> 96963494 | AC16: %
B18: All values are in AED | R18: All values are in AED
A20: Staff Performance | Q20: Month-wise Split
D22: No. of Packages | G22: Awarded | J22: Savings | M22: % Savings | T22: Awarded | W22: % Savings
R23: 2025
B24: Anil | D24: ='Total Summary'!E20 -> 0 | G24: ='Total Summary'!F20 -> 0 | J24: ='Total Summary'!G20 -> 0 | M24: % | R24: December | T24: ='Total Summary'!F34 -> 4355584 | W24: ='Total Summary'!H34 -> 0.012016396
B25: Prabhu | D25: ='Total Summary'!E21 -> 3 | G25: ='Total Summary'!F21 -> 28533905 | J25: ='Total Summary'!G21 -> -2173246 | M25: %
B26: Manoj | D26: ='Total Summary'!E22 -> 3 | G26: ='Total Summary'!F22 -> 50841356 | J26: ='Total Summary'!G22 -> 3656010.2 | M26: % | R26: 2026
B27: Iftikhar | D27: ='Total Summary'!E23 -> 4 | G27: ='Total Summary'!F23 -> 47288743 | J27: ='Total Summary'!G23 -> 29224257 | M27: % | R27: January | T27: ='Total Summary'!F35 -> 26978980 | W27: ='Total Summary'!H35 -> 0.074430913
B28: Alber | D28: ='Total Summary'!E24 -> 3 | G28: ='Total Summary'!F24 -> 6670883 | J28: ='Total Summary'!G24 -> 2132940 | M28: % | R28: February | T28: ='Total Summary'!F36 -> 1969878.2 | W28: ='Total Summary'!H36 -> 0.005434595
B29: Abeer | D29: ='Total Summary'!E25 -> 0 | G29: ='Total Summary'!F25 -> 0 | J29: ='Total Summary'!G25 -> 0 | M29: % | R29: March | T29: ='Total Summary'!F37 -> 10704455 | W29: ='Total Summary'!H37 -> 0.029531969
B30: Suhail | D30: ='Total Summary'!E26 -> 3 | G30: ='Total Summary'!F26 -> 1.7862546e+08 | J30: ='Total Summary'!G26 -> 62326070 | M30: % | R30: April | T30: ='Total Summary'!F38 -> 1.6077931e+08 | W30: ='Total Summary'!H38 -> 0.44356572
B31: Reyoon | D31: ='Total Summary'!E27 -> 6 | G31: ='Total Summary'!F27 -> 28112522 | J31: ='Total Summary'!G27 -> 2448906.2 | M31: % | R31: May | T31: ='Total Summary'!F39 -> 1.1575009e+08 | W31: ='Total Summary'!H39 -> 0.31933694
B32: FW Pkg | D32: ='Total Summary'!E28 -> 2 | G32: ='Total Summary'!F28 -> 5259932.6 | J32: ='Total Summary'!G28 -> -651443.02 | M32: % | R32: June | T32: ='Total Summary'!F40 -> 41931797 | W32: ='Total Summary'!H40 -> 0.11568347
R33: July | T33: ='Total Summary'!F41 -> 0 | W33: ='Total Summary'!H41 -> 0
B34: Total | D34: =SUM(D23:E33) -> 24 | G34: =SUM(G23:H33) -> 3.453328e+08 | J34: =SUM(J23:K33) -> 96963494 | M34: 0 | R34: August | T34: ='Total Summary'!F41 -> 0 | W34: ='Total Summary'!H42 -> 0 | Z34: Total | AB34: =SUM(AB20:AC22) -> 0 | AC34: =SUM(T24:U38) -> 3.6247009e+08
R35: September | T35: ='Total Summary'!F42 -> 0 | W35: ='Total Summary'!H43 -> 0
B36: All values are in AED | R36: October | T36: ='Total Summary'!F48 -> 0 | W36: ='Total Summary'!H44 -> 0 | AC36: %
R37: November | W37: ='Total Summary'!H45 -> 0
R38: December | T38: ='Total Summary'!F50 -> 0 | W38: ='Total Summary'!H46 -> 0
R40: All values are in AED

Sheet ARR 
B2: ARR updated Status
B3: # | C3: Project name | D3: Package Name | E3: Type of works | F3: Subcontractor | G3: PS Amount Incl OH&P | H3: Awarded Amount Include OH&P | I3: Saving/Loss | J3: Date | K3: Month | L3: PM | M3: Location | N3: Status | O3: Remarks
B5: 1 | C5: Nobu | G5: =SUM(G6:G14) -> 38554161 | H5: =SUM(H6:H14) -> 34234823 | I5: =SUM(I6:I14) -> 4319337.5
B6: 1 | D6: Parking Accessories | E6: Supply & Install | F6: Ocean Rubber Fcatory | G6: 309296 | H6: 238510 | I6: =IF(H6>0,G6-H6,"") -> 70786 | J6: 46153 | K6: =TEXT(J6,"mmm yyyy") -> May 2026 | L6: Alber | M6: Abu Dhabi | N6: Awarded | O6: 11% OH&P
B7: =IF(D7>0,B6+1,"") -> 2 | D7: Kitchen and Wardrobes | E7: Supply & Install | F7: Molteni ( Italy) | G7: 23043531 | H7: 25437103 | I7: =IF(H7>0,G7-H7,"") -> -2393572.5 | J7: 46150 | K7: =TEXT(J7,"mmm yyyy") -> May 2026 | L7: Suhail | M7: Abu Dhabi | N7: Awarded | O7: 11% OH&P
B8: =IF(D8>0,B7+1,"") -> 3 | D8: Light Fittings | E8: Supply only | F8: Istanboul Group | G8: 10000000 | H8: 2801886 | I8: =IF(H8>0,G8-H8,"") -> 7198114 | J8: 46149 | K8: =TEXT(J8,"mmm yyyy") -> May 2026 | L8: Manoj | M8: Abu Dhabi | N8: Awarded | O8: 11% OH&P
B9: =IF(D9>0,B8+1,"") -> 4 | D9: Sauna & Steam | E9: Supply & Install | F9: Sports Line | G9: 592844 | H9: 497391 | I9: =IF(H9>0,G9-H9,"") -> 95453 | J9: 46141 | K9: =TEXT(J9,"mmm yyyy") -> Apr 2026 | L9: Prabhu | M9: Abu Dhabi | N9: Awarded | O9: 11% OH&P
B10: =IF(D10>0,B9+1,"") -> 5 | D10: White Goods Package | E10: Supply & Install | F10: Miele | G10: 4608489.6 | H10: 5259932.6 | I10: =IF(H10>0,G10-H10,"") -> -651443.02 | J10: 46153 | K10: =TEXT(J10,"mmm yyyy") -> May 2026 | L10: Frameworks Agreement | M10: Abu Dhabi | N10: Awarded | O10: 11% OH&P
B11: =IF(D11>0,B10+1,"") -> 6 | D11: Signage | E11: Supply & Install | I11: =IF(H11>0,G11-H11,"") | K11: =TEXT(J11,"mmm yyyy") -> Jan 1900 | L11: Alber | M11: Abu Dhabi | N11: Ongoing | O11: 11% OH&P
B12: =IF(D12>0,B11+1,"") -> 7 | D12: Metal Works (Parking) | E12: Supply & Install | I12: =IF(H12>0,G12-H12,"") | K12: =TEXT(J12,"mmm yyyy") -> Jan 1900 | L12: Alber | M12: Abu Dhabi | N12: Ongoing | O12: 11% OH&P
B13: =IF(D13>0,B12+1,"") | I13: =IF(H13>0,G13-H13,"") | K13: =TEXT(J13,"mmm yyyy") -> Jan 1900
I14: =IF(H14>0,G14-H14,"") | K14: =TEXT(J14,"mmm yyyy") -> Jan 1900
B15: 2 | C15: Verdes | G15: =SUM(G16:G21) -> 39004168 | H15: =SUM(H16:H21) -> 21936231 | I15: =SUM(I16:I21) -> 17067937
B16: 1 | D16: Light Fittings | E16: Supply only | F16: Istanboul Group | G16: 14000000 | H16: 2166248 | I16: =IF(H16>0,G16-H16,"") -> 11833752 | J16: 46149 | K16: =TEXT(J16,"mmm yyyy") -> May 2026 | L16: Iftikhar | M16: Dubai | N16: Awarded | O16: 3% OH&P
B17: =IF(D17>0,B16+1,"") -> 2 | D17: Sanitaryware | E17: Supply only | F17: SARA Group Innovo | G17: 17000000 | H17: 13787931 | I17: =IF(H17>0,G17-H17,"") -> 3212068.9 | J17: 46164 | K17: =TEXT(J17,"mmm yyyy") -> May 2026 | L17: Iftikhar | M17: Dubai | N17: Awarded | O17: 3% OH&P
B18: =IF(D18>0,B17+1,"") -> 3 | D18: Tile PC rate | E18: Supply only | F18: RAK | G18: 8004168 | H18: 5982052 | I18: =IF(H18>0,G18-H18,"") -> 2022116 | J18: 46174 | K18: =TEXT(J18,"mmm yyyy") -> Jun 2026 | L18: Alber | M18: Dubai | N18: Awarded | O18: 3% OH&P
B19: =IF(D19>0,B18+1,"") | I19: =IF(H19>0,G19-H19,"") | K19: =TEXT(J19,"mmm yyyy") -> Jan 1900
B20: =IF(D20>0,B19+1,"") | I20: =IF(H20>0,G20-H20,"") | K20: =TEXT(J20,"mmm yyyy") -> Jan 1900
I21: =IF(H21>0,G21-H21,"") | K21: =TEXT(J21,"mmm yyyy") -> Jan 1900
B22: 3 | C22: Al Marjan | G22: =SUM(G23:G29) -> 369300000 | H22: =SUM(H23:H29) -> 1.7358384e+08 | I22: =SUM(I23:I29) -> 69216158
B23: 1 | D23: GRC | E23: Supply & Install | F23: Extraco | G23: 25000000 | H23: 26531027 | I23: =IF(H23>0,G23-H23,"") -> -1531027 | J23: 46150 | K23: =TEXT(J23,"mmm yyyy") -> May 2026 | L23: Prabhu | M23: RAK | N23: Awarded | O23: 11% OH&P
B24: =IF(D24>0,B23+1,"") -> 2 | D24: Joinery Works | E24: Supply & Install | F24: AL SHAYA TRADING INNOVO SOLUTIONS | G24: 181500000 | H24: 1.2007383e+08 | I24: =IF(H24>0,G24-H24,"") -> 61426165 | J24: 46142 | K24: =TEXT(J24,"mmm yyyy") -> Apr 2026 | L24: Suhail | M24: RAK | N24: Awarded | O24: 11% OH&P
B25: =IF(D25>0,B24+1,"") -> 3 | D25: Sanitaryware | E25: Supply only | F25: Al Hasimya Sarieddine | G25: 36300000 | H25: 26978980 | I25: =IF(H25>0,G25-H25,"") -> 9321020 | J25: 46045 | K25: =TEXT(J25,"mmm yyyy") -> Jan 2026 | L25: Iftikhar | M25: RAK | N25: Awarded | O25: 11% OH&P Changes in quantities & design selection
B26: =IF(D26>0,B25+1,"") -> 4 | D26: Finishes | E26: Supply & Install | F26: TBC | G26: 126500000 | I26: =IF(H26>0,G26-H26,"") | K26: =TEXT(J26,"mmm yyyy") -> Jan 1900 | L26: Reyoon | M26: RAK | N26: Ongoing
B27: =IF(D27>0,B26+1,"") | I27: =IF(H27>0,G27-H27,"") | K27: =TEXT(J27,"mmm yyyy") -> Jan 1900
B28: =IF(D28>0,B27+1,"") | I28: =IF(H28>0,G28-H28,"") | K28: =TEXT(J28,"mmm yyyy") -> Jan 1900
I29: =IF(H29>0,G29-H29,"") | K29: =TEXT(J29,"mmm yyyy") -> Jan 1900
B30: 4 | C30: Sama Yas | G30: =SUM(G31:G39) -> 45621000 | H30: =SUM(H31:H39) -> 37470106 | I30: =SUM(I31:I39) -> 8150893.6
B31: 1 | D31: Joinery works | E31: Supply & Install | F31: INNOVO SOLUTIONS | G31: 36408000 | H31: 33114522 | I31: =IF(H31>0,G31-H31,"") -> 3293477.6 | J31: 46146 | K31: =TEXT(J31,"mmm yyyy") -> May 2026 | L31: Suhail | M31: Abu Dhabi | N31: Awarded | O31: 11% OH&P
B32: =IF(D32>0,B31+1,"") -> 2 | D32: Sanitaryware | E32: Supply only | F32: Al Hashimya Sanitary Material | G32: 9213000 | H32: 4355584 | I32: =IF(H32>0,G32-H32,"") -> 4857416 | J32: 46013 | K32: =TEXT(J32,"mmm yyyy") -> Dec 2025 | L32: Iftikhar | M32: Abu Dhabi | N32: Awarded | O32: 11% OH&P Changes in quantities & design selection
B33: =IF(D33>0,B32+1,"") | I33: =IF(H33>0,G33-H33,"") | K33: =TEXT(J33,"mmm yyyy") -> Jan 1900
B34: =IF(D34>0,B33+1,"") | I34: =IF(H34>0,G34-H34,"") | K34: =TEXT(J34,"mmm yyyy") -> Jan 1900
B35: =IF(D35>0,B34+1,"") | I35: =IF(H35>0,G35-H35,"") | K35: =TEXT(J35,"mmm yyyy") -> Jan 1900
B36: =IF(D36>0,B35+1,"") | I36: =IF(H36>0,G36-H36,"") | K36: =TEXT(J36,"mmm yyyy") -> Jan 1900
B37: =IF(D37>0,B36+1,"") | I37: =IF(H37>0,G37-H37,"") | K37: =TEXT(J37,"mmm yyyy") -> Jan 1900
B38: =IF(D38>0,B37+1,"") | I38: =IF(H38>0,G38-H38,"") | K38: =TEXT(J38,"mmm yyyy") -> Jan 1900
I39: =IF(H39>0,G39-H39,"") | K39: =TEXT(J39,"mmm yyyy") -> Jan 1900
B40: 5 | C40: Mamsha Palm | G40: =SUM(G41:G52) -> 46517000 | H40: =SUM(H41:H52) -> 39757760 | I40: =SUM(I41:I52) -> -1677760
B41: 1 | D41: MEP works | E41: Supply & Install | F41: OXYPRO | G41: 38080000 | H41: 39757760 | I41: =IF(H41>0,G41-H41,"") -> -1677760 | J41: 46139 | K41: =TEXT(J41,"mmm yyyy") -> Apr 2026 | L41: Manoj | M41: Abu Dhabi | N41: Awarded | O41: 12% OH&P
B42: =IF(D42>0,B41+1,"") -> 2 | D42: BMU | E42: Supply & Install | I42: =IF(H42>0,G42-H42,"") | K42: =TEXT(J42,"mmm yyyy") -> Jan 1900 | L42: Abeer | M42: Abu Dhabi | N42: Ongoing
...
